<?xml version="1.0" ?>
<robot name="kangre_autonomo" xmlns:xacro="http://www.ros.org/wiki/xacro">

<xacro:include filename="$(find kangre_autonomo_description)/urdf/materials.xacro" />
<xacro:include filename="$(find kangre_autonomo_description)/urdf/kangre_autonomo.trans" />
<xacro:include filename="$(find kangre_autonomo_description)/urdf/kangre_autonomo.gazebo" />
<link name="base_link">
  <inertial>
    <origin xyz="0.020465540808401114 1.2962818327265716e-05 0.0656689943374941" rpy="0 0 0.0"/>
    <mass value="1.2373061159976249"/>
    <inertia ixx="0.006438" iyy="0.008276" izz="0.011206" ixy="-2.9e-05" iyz="1e-05" ixz="-0.000628"/>
  </inertial>
  <visual>
    <origin xyz="0 0 0" rpy="0 0 0"/>
    <geometry>
      <mesh filename="package://kangre_autonomo_description/meshes/base_link.stl" scale="0.001 0.001 0.001"/>
    </geometry>
    <material name="silver"/>
  </visual>
  <collision>
    <origin xyz="0 0 0" rpy="0 0 0"/>
    <geometry>
      <mesh filename="package://kangre_autonomo_description/meshes/base_link.stl" scale="0.001 0.001 0.001"/>
    </geometry>
  </collision>
</link>

<link name="wheel_r_1">
  <inertial>
    <origin xyz="1.922572021723079e-08 -0.018806075124693095 3.907370817110567e-07" rpy="0 0 0"/>
    <mass value="0.031502771992212734"/>
    <inertia ixx="1.3e-05" iyy="2.2e-05" izz="1.3e-05" ixy="0.0" iyz="-0.0" ixz="-0.0"/>
  </inertial>
  <visual>
    <origin xyz="-0.048275 0.064037 -0.033797" rpy="0 0 0"/>
    <geometry>
      <mesh filename="package://kangre_autonomo_description/meshes/wheel_r_1.stl" scale="0.001 0.001 0.001"/>
    </geometry>
    <material name="silver"/>
  </visual>
  <collision>
    <origin xyz="-0.048275 0.064037 -0.033797" rpy="0 0 0"/>
    <geometry>
      <mesh filename="package://kangre_autonomo_description/meshes/wheel_r_1.stl" scale="0.001 0.001 0.001"/>
    </geometry>
  </collision>
</link>

<link name="wheel_l_1">
  <inertial>
    <origin xyz="2.1703950083690193e-07 0.01880701263718529 3.9073708188452905e-07" rpy="0 0 0"/>
    <mass value="0.031502771992212734"/>
    <inertia ixx="1.3e-05" iyy="2.2e-05" izz="1.3e-05" ixy="0.0" iyz="0.0" ixz="0.0"/>
  </inertial>
  <visual>
    <origin xyz="-0.048325 -0.064963 -0.033797" rpy="0 0 0"/>
    <geometry>
      <mesh filename="package://kangre_autonomo_description/meshes/wheel_l_1.stl" scale="0.001 0.001 0.001"/>
    </geometry>
    <material name="silver"/>
  </visual>
  <collision>
    <origin xyz="-0.048325 -0.064963 -0.033797" rpy="0 0 0"/>
    <geometry>
      <mesh filename="package://kangre_autonomo_description/meshes/wheel_l_1.stl" scale="0.001 0.001 0.001"/>
    </geometry>
  </collision>
</link>

<link name="caster_r_1">
  <inertial>
    <origin xyz="-9.043532518682174e-08 9.9101123406109e-07 -0.005614632437278418" rpy="0 0 0"/>
    <mass value="0.0019379953577739798"/>
    <inertia ixx="0.0" iyy="0.0" izz="0.0" ixy="-0.0" iyz="-0.0" ixz="0.0"/>
  </inertial>
  <visual>
    <origin xyz="0.089175 0.039537 -0.014297" rpy="0 0 0"/>
    <geometry>
      <mesh filename="package://kangre_autonomo_description/meshes/caster_r_1.stl" scale="0.001 0.001 0.001"/>
    </geometry>
    <material name="silver"/>
  </visual>
  <collision>
    <origin xyz="0.089175 0.039537 -0.014297" rpy="0 0 0"/>
    <geometry>
      <mesh filename="package://kangre_autonomo_description/meshes/caster_r_1.stl" scale="0.001 0.001 0.001"/>
    </geometry>
  </collision>
</link>

<link name="caster_l_1">
  <inertial>
    <origin xyz="-8.653395604241165e-08 9.910112341998678e-07 -0.005614632437278423" rpy="0 0 0"/>
    <mass value="0.0019379953577739798"/>
    <inertia ixx="0.0" iyy="0.0" izz="0.0" ixy="-0.0" iyz="-0.0" ixz="0.0"/>
  </inertial>
  <visual>
    <origin xyz="0.089175 -0.040463 -0.014297" rpy="0 0 0"/>
    <geometry>
      <mesh filename="package://kangre_autonomo_description/meshes/caster_l_1.stl" scale="0.001 0.001 0.001"/>
    </geometry>
    <material name="silver"/>
  </visual>
  <collision>
    <origin xyz="0.089175 -0.040463 -0.014297" rpy="0 0 0"/>
    <geometry>
      <mesh filename="package://kangre_autonomo_description/meshes/caster_l_1.stl" scale="0.001 0.001 0.001"/>
    </geometry>
  </collision>
</link>

<link name="lidar_v1_1">
  <inertial>
    <origin xyz="-0.00036382402145790707 0.0032365140144362914 0.01320002692671135" rpy="0.0 0.0 0.0"/>
    <mass value="0.010966232720504534"/>
    <inertia ixx="5e-06" iyy="5e-06" izz="1e-05" ixy="0.0" iyz="-0.0" ixz="0.0"/>
  </inertial>
  <visual>
    <origin xyz="-0.010825 -0.000463 -0.152997" rpy="0.0 0 0.0"/>
    <geometry>
      <mesh filename="package://kangre_autonomo_description/meshes/lidar_v1_1.stl" scale="0.001 0.001 0.001"/>
    </geometry>
    <material name="silver"/>
  </visual>
  <collision>
    <origin xyz="-0.010825 -0.000463 -0.152997" rpy="0.0 0 0.0"/>
    <geometry>
      <mesh filename="package://kangre_autonomo_description/meshes/lidar_v1_1.stl" scale="0.001 0.001 0.001"/>
    </geometry>
  </collision>
</link>

<joint name="Rev7" type="continuous">
  <origin xyz="0.048275 -0.064037 0.033797" rpy="0 0 0"/>
  <parent link="base_link"/>
  <child link="wheel_r_1"/>
  <axis xyz="0.0 1.0 -0.0"/>
</joint>

<joint name="Rev8" type="continuous">
  <origin xyz="0.048325 0.064963 0.033797" rpy="0 0 0"/>
  <parent link="base_link"/>
  <child link="wheel_l_1"/>
  <axis xyz="-0.0 1.0 0.0"/>
</joint>

<joint name="Rigid9" type="fixed">
  <origin xyz="-0.089175 -0.039537 0.014297" rpy="0 0 0"/>
  <parent link="base_link"/>
  <child link="caster_r_1"/>
</joint>

<joint name="Rigid10" type="fixed">
  <origin xyz="-0.089175 0.040463 0.014297" rpy="0 0 0"/>
  <parent link="base_link"/>
  <child link="caster_l_1"/>
</joint>

<joint name="Rigid11" type="fixed">
  <origin xyz="0.010825 0.000463 0.152997" rpy="0 0 3.14"/>
  <parent link="base_link"/>
  <child link="lidar_v1_1"/>
</joint>

</robot>
